[2025-04-29T17:23:19.881-0400] {taskinstance.py:1083} INFO - Dependencies all met for <TaskInstance: opportunity_pipeline.ingest_airtable scheduled__2025-04-28T21:00:00+00:00 [queued]>
[2025-04-29T17:23:19.885-0400] {taskinstance.py:1083} INFO - Dependencies all met for <TaskInstance: opportunity_pipeline.ingest_airtable scheduled__2025-04-28T21:00:00+00:00 [queued]>
[2025-04-29T17:23:19.885-0400] {taskinstance.py:1279} INFO - 
--------------------------------------------------------------------------------
[2025-04-29T17:23:19.885-0400] {taskinstance.py:1280} INFO - Starting attempt 1 of 2
[2025-04-29T17:23:19.885-0400] {taskinstance.py:1281} INFO - 
--------------------------------------------------------------------------------
[2025-04-29T17:23:19.890-0400] {taskinstance.py:1300} INFO - Executing <Task(PythonOperator): ingest_airtable> on 2025-04-28 21:00:00+00:00
[2025-04-29T17:23:19.892-0400] {standard_task_runner.py:55} INFO - Started process 32319 to run task
[2025-04-29T17:23:19.895-0400] {standard_task_runner.py:82} INFO - Running: ['airflow', 'tasks', 'run', 'opportunity_pipeline', 'ingest_airtable', 'scheduled__2025-04-28T21:00:00+00:00', '--job-id', '4', '--raw', '--subdir', 'DAGS_FOLDER/opportunity_ingest_dag.py', '--cfg-path', '/var/folders/bc/zt35hlqn755d7y9zj64rxxph0000gn/T/tmpzobw61_p']
[2025-04-29T17:23:19.897-0400] {standard_task_runner.py:83} INFO - Job 4: Subtask ingest_airtable
[2025-04-29T17:23:19.940-0400] {task_command.py:388} INFO - Running <TaskInstance: opportunity_pipeline.ingest_airtable scheduled__2025-04-28T21:00:00+00:00 [running]> on host zihaos-macbook-pro.local
[2025-04-29T17:23:19.966-0400] {taskinstance.py:1507} INFO - Exporting the following env vars:
AIRFLOW_CTX_DAG_OWNER=you
AIRFLOW_CTX_DAG_ID=opportunity_pipeline
AIRFLOW_CTX_TASK_ID=ingest_airtable
AIRFLOW_CTX_EXECUTION_DATE=2025-04-28T21:00:00+00:00
AIRFLOW_CTX_TRY_NUMBER=1
AIRFLOW_CTX_DAG_RUN_ID=scheduled__2025-04-28T21:00:00+00:00
[2025-04-29T17:23:40.074-0400] {local_task_job.py:272} WARNING - State of this instance has been externally set to queued. Terminating instance.
[2025-04-29T17:23:40.085-0400] {process_utils.py:129} INFO - Sending 15 to group 32319. PIDs of all processes in the group: [32319]
[2025-04-29T17:23:40.086-0400] {process_utils.py:84} INFO - Sending the signal 15 to group 32319
[2025-04-29T17:24:40.097-0400] {process_utils.py:147} WARNING - process psutil.Process(pid=32319, name='Python', status='running', started='17:23:19') did not respond to SIGTERM. Trying SIGKILL
[2025-04-29T17:24:40.101-0400] {process_utils.py:84} INFO - Sending the signal 9 to group 32319
[2025-04-29T17:24:40.109-0400] {process_utils.py:79} INFO - Process psutil.Process(pid=32319, name='Python', status='terminated', exitcode=<Negsignal.SIGKILL: -9>, started='17:23:19') (32319) terminated with exit code -9
[2025-04-29T17:24:40.110-0400] {standard_task_runner.py:168} ERROR - Job 4 was killed before it finished (likely due to running out of memory)
